Workbook

Sheet 요약
A1: WeaponHero — 1회전 테스트 결과
A3: 테스트 목적 | B3: 1차 제출 빌드의 회귀 확인과 경계·비정상 흐름 검증
A4: 테스트 빌드 | B4: v1.0 (2026-09-03 제출본) · Windows x64
A5: 테스트 기간 | B5: 2026-09-23 ~ 2026-09-24 · 세션 8회
A6: 테스트 인원 | B6: 1명 (손주환)
A7: 테스트 환경 | B7: Windows 11 Home 24H2 · Ryzen 5 9600X · RX 9070 XT · 32GB · 2560×1440
A8: 엔진 | B8: Unity 6000.3.15f1 · URP 2D
A9: 원본 문서 | B9: docs/qa/test-cases.md · docs/qa/test-run-log.md · docs/qa/test-plan.md · docs/qa/test-steps-draft.md
A10: 생성일 | B10: 2026-09-24
A11: 테스트 스텝과 사전 조건은 2026-09-28 초안이다 — 2회전에서 수행하며 확정한다
A12: [결과] 는 최신 회차다. 1회전 결과는 [1회전 결과] 열에 남겨 같은 줄에서 수정 전후가 보이게 했다 — 집계와 그래프는 [결과] 를 센다
A13: 결과 집계
A14: 구분 | B14: 건수 | C14: 비율
A15: Pass | B15: =COUNTIF('TC 목록'!$H$2:$H$110,A15) | C15: =IFERROR(B15/$B$19,0)
A16: Fail | B16: =COUNTIF('TC 목록'!$H$2:$H$110,A16) | C16: =IFERROR(B16/$B$19,0)
A17: N/A | B17: =COUNTIF('TC 목록'!$H$2:$H$110,A17) | C17: =IFERROR(B17/$B$19,0)
A18: 미확인 | B18: =COUNTIF('TC 목록'!$H$2:$H$110,A18) | C18: =IFERROR(B18/$B$19,0)
A19: 합계 | B19: =SUM(B15:B18)
A21: 영역별
A22: 영역 | B22: 항목 | C22: Pass | D22: Fail
A23: 이동 · 점프 | B23: =COUNTIF('TC 목록'!$B$2:$B$110,$A23) | C23: =COUNTIFS('TC 목록'!$B$2:$B$110,$A23,'TC 목록'!$H$2:$H$110,"Pass") | D23: =COUNTIFS('TC 목록'!$B$2:$B$110,$A23,'TC 목록'!$H$2:$H$110,"Fail")
A24: 전투 · 피격 | B24: =COUNTIF('TC 목록'!$B$2:$B$110,$A24) | C24: =COUNTIFS('TC 목록'!$B$2:$B$110,$A24,'TC 목록'!$H$2:$H$110,"Pass") | D24: =COUNTIFS('TC 목록'!$B$2:$B$110,$A24,'TC 목록'!$H$2:$H$110,"Fail")
A25: 무기 스왑 | B25: =COUNTIF('TC 목록'!$B$2:$B$110,$A25) | C25: =COUNTIFS('TC 목록'!$B$2:$B$110,$A25,'TC 목록'!$H$2:$H$110,"Pass") | D25: =COUNTIFS('TC 목록'!$B$2:$B$110,$A25,'TC 목록'!$H$2:$H$110,"Fail")
A26: 무기 · 투사체 | B26: =COUNTIF('TC 목록'!$B$2:$B$110,$A26) | C26: =COUNTIFS('TC 목록'!$B$2:$B$110,$A26,'TC 목록'!$H$2:$H$110,"Pass") | D26: =COUNTIFS('TC 목록'!$B$2:$B$110,$A26,'TC 목록'!$H$2:$H$110,"Fail")
A27: 적 · 보스 | B27: =COUNTIF('TC 목록'!$B$2:$B$110,$A27) | C27: =COUNTIFS('TC 목록'!$B$2:$B$110,$A27,'TC 목록'!$H$2:$H$110,"Pass") | D27: =COUNTIFS('TC 목록'!$B$2:$B$110,$A27,'TC 목록'!$H$2:$H$110,"Fail")
A28: 방 · 스테이지 | B28: =COUNTIF('TC 목록'!$B$2:$B$110,$A28) | C28: =COUNTIFS('TC 목록'!$B$2:$B$110,$A28,'TC 목록'!$H$2:$H$110,"Pass") | D28: =COUNTIFS('TC 목록'!$B$2:$B$110,$A28,'TC 목록'!$H$2:$H$110,"Fail")
A29: 런 루프 · 보상 | B29: =COUNTIF('TC 목록'!$B$2:$B$110,$A29) | C29: =COUNTIFS('TC 목록'!$B$2:$B$110,$A29,'TC 목록'!$H$2:$H$110,"Pass") | D29: =COUNTIFS('TC 목록'!$B$2:$B$110,$A29,'TC 목록'!$H$2:$H$110,"Fail")
A30: UI · 설정 · 로컬라이즈 | B30: =COUNTIF('TC 목록'!$B$2:$B$110,$A30) | C30: =COUNTIFS('TC 목록'!$B$2:$B$110,$A30,'TC 목록'!$H$2:$H$110,"Pass") | D30: =COUNTIFS('TC 목록'!$B$2:$B$110,$A30,'TC 목록'!$H$2:$H$110,"Fail")
A31: 소리 | B31: =COUNTIF('TC 목록'!$B$2:$B$110,$A31) | C31: =COUNTIFS('TC 목록'!$B$2:$B$110,$A31,'TC 목록'!$H$2:$H$110,"Pass") | D31: =COUNTIFS('TC 목록'!$B$2:$B$110,$A31,'TC 목록'!$H$2:$H$110,"Fail")
A32: 경계 · 비정상 흐름 | B32: =COUNTIF('TC 목록'!$B$2:$B$110,$A32) | C32: =COUNTIFS('TC 목록'!$B$2:$B$110,$A32,'TC 목록'!$H$2:$H$110,"Pass") | D32: =COUNTIFS('TC 목록'!$B$2:$B$110,$A32,'TC 목록'!$H$2:$H$110,"Fail")
A33: 빌드 전 정적 확인 | B33: =COUNTIF('TC 목록'!$B$2:$B$110,$A33) | C33: =COUNTIFS('TC 목록'!$B$2:$B$110,$A33,'TC 목록'!$H$2:$H$110,"Pass") | D33: =COUNTIFS('TC 목록'!$B$2:$B$110,$A33,'TC 목록'!$H$2:$H$110,"Fail")
A35: 이번 회전 신규 결함 7건 — 상세는 [결함] 시트
A36: 실패 12건 = 과거 빌드에서 잡아 수정한 4건 · 이번 회전 신규 7건 · 이연 1건. 상세는 [결과 보고서] 시트
A37: 미확인(△) 0건 — 확인하지 못한 항목을 통과로 적지 않는 것이 이 표의 규칙이다.

Sheet TC 목록
A1: NO | B1: 대분류 | C1: 중분류 | D1: 소분류(확인 항목) | E1: 사전 조건 | F1: 테스트 스텝 | G1: 기대 결과 | H1: 결과 | I1: 1회전 결과 | J1: 비고 | K1: BTS 링크 | L1: 중요도 | M1: 우선순위 | N1: 테스트 날짜
A2: 1 | B2: 이동 · 점프 | C2: 이동 · 점프 | D2: TC-MOVE-01 좌우 이동 | E2: 새 런 시작 · 전투방 1 진입 · 적 처치 전 | F2: 1. ← 를 2초 누른다 2. → 를 2초 누른다 3. 이동 방향과 스프라이트가 바라보는 쪽을 본다 | G2: 입력 방향으로 이동하고 스프라이트가 뒤집힌다 | H2: Pass | I2: Pass | N2: 2026-10-03
A3: 2 | B3: 이동 · 점프 | C3: 이동 · 점프 | D3: TC-MOVE-02 가변 높이 점프 | E3: 새 런 시작 · 전투방 1 진입 · 적 처치 전 | F3: 1. Space 를 아주 짧게 눌러 떼고 점프 높이를 본다 2. 같은 자리에서 Space 를 끝까지 누른 채 점프한다 3. 두 높이를 비교한다 | G3: 버튼을 짧게 떼면 낮게, 끝까지 누르면 높게 뛴다 | H3: Pass | I3: Pass | N3: 2026-10-03
A4: 3 | B4: 이동 · 점프 | C4: 이동 · 점프 | D4: TC-MOVE-03 코요테 타임 | E4: 새 런 시작 · 전투방 1 진입 · 적 처치 전 | F4: 1. 발판 끝까지 걸어간다 2. 발판을 벗어난 직후(0.1초 안에) Space 를 누른다 3. 점프가 나가는지 본다 | G4: 발판을 떠난 직후에 눌러도 점프가 나간다 | H4: Pass | I4: Pass | N4: 2026-10-03
A5: 4 | B5: 이동 · 점프 | C5: 이동 · 점프 | D5: TC-MOVE-04 점프 버퍼 | E5: 새 런 시작 · 전투방 1 진입 · 적 처치 전 | F5: 1. 높은 곳에서 아래로 떨어진다 2. 착지하기 직전(공중에서) Space 를 누른다 3. 착지와 함께 점프가 나가는지 본다 | G5: 착지 직전에 눌러도 점프가 씹히지 않는다 | H5: Pass | I5: Pass | N5: 2026-10-03
A6: 5 | B6: 이동 · 점프 | C6: 이동 · 점프 | D6: TC-MOVE-05 낙하 복귀 | E6: 새 런 시작 · 전투방 1 진입 · 적 처치 전 | F6: 1. 방 안의 구멍(낙하 지점)을 찾아 그 위에 선다 2. 구멍으로 떨어진다 3. 복귀한 위치가 떨어지기 전 마지막으로 발을 붙였던 지점인지 본다 | G6: 구멍에 떨어지면 마지막 접지 지점으로 돌아온다 | H6: Pass | I6: Pass | N6: 2026-10-03
A7: 6 | B7: 전투 · 피격 | C7: 전투 · 피격 | D7: TC-CMB-01 3타 콤보와 선입력 | E7: 새 런 시작 · 전투방 1 · 적 1마리 이상 생존 · 활성 무기 검 | F7: 1. 적 앞에서 F 를 누른다 2. 1타 모션이 끝나기 전에 F 를 다시 누른다 3. 같은 방식으로 3타까지 이어 누른다 4. 세 타가 끊기지 않고 이어지는지 본다 | G7: 연속 입력이 다음 타로 이어진다 | H7: Pass | I7: Pass | N7: 2026-10-03
A8: 7 | B8: 전투 · 피격 | C8: 전투 · 피격 | D8: TC-CMB-02 콤보 타임아웃 | E8: 새 런 시작 · 전투방 1 · 적 1마리 이상 생존 · 활성 무기 검 | F8: 1. F 로 1타를 낸다 2. 아무 입력 없이 2초 기다린다 3. 다시 F 를 누른다 4. 나가는 모션이 2타인지 1타인지 본다 | G8: 입력이 끊기면 1타부터 다시 시작한다 | H8: Pass | I8: Pass | N8: 2026-10-03
A9: 8 | B9: 전투 · 피격 | C9: 전투 · 피격 | D9: TC-CMB-03 히트스탑 · 넉백 · 화면 흔들림 | E9: 새 런 시작 · 전투방 1 · 적 1마리 이상 생존 · 활성 무기 검 | F9: 1. 적에게 F 로 한 대 맞힌다 2. 타격이 닿는 순간 화면을 본다 3. 셋이 동시에 나는지 각각 확인한다 — 동작이 멈추는가 · 적이 밀리는가 · 화면이 흔들리는가 | G9: 타격 순간 셋이 함께 난다 | H9: Pass | I9: Pass | N9: 2026-10-03
A10: 9 | B10: 전투 · 피격 | C10: 전투 · 피격 | D10: TC-CMB-04 피격 무적과 깜빡임 | E10: 새 런 시작 · 전투방 1 · 적 1마리 이상 생존 · 활성 무기 검 | F10: 1. 적 공격에 일부러 한 번 맞는다 2. 맞은 직후 적 앞에 그대로 서 있는다 3. 스프라이트가 깜빡이는 동안 HUD 체력이 더 줄어드는지 본다 | G10: 맞으면 깜빡이고 그동안 다시 안 맞는다 | H10: Pass | I10: Pass | N10: 2026-10-03
A11: 10 | B11: 전투 · 피격 | C11: 전투 · 피격 | D11: TC-CMB-05 적 둘 사이 연속 피격 | E11: 새 런 시작 · 전투방 1 · 적 1마리 이상 생존 · 활성 무기 검 | F11: 1. 적 2마리가 함께 있는 방에서 둘 사이로 들어간다 2. 한쪽 공격에 맞는다 3. 깜빡이는 동안 다른 쪽 공격에 몸을 댄다 4. 두 번째 피해가 들어가는지 본다 | G11: 무적 중에 두 번째 적에게 이어서 안 갈린다 | H11: Pass | I11: Pass | N11: 2026-10-03
A12: 11 | B12: 전투 · 피격 | C12: 전투 · 피격 | D12: TC-CMB-06 지상 공격 중 전진 | E12: 새 런 시작 · 전투방 1 · 적 1마리 이상 생존 · 활성 무기 검 | F12: 1. 지상에서 적과 조금 떨어져 선다 2. 발 위치를 기억하고 F 를 누른다 3. 공격이 끝난 뒤 발 위치가 앞으로 옮겨졌는지 본다 | G12: 공격하면서 조금 앞으로 나간다 | H12: Pass | I12: Pass | N12: 2026-10-03
A13: 12 | B13: 전투 · 피격 | C13: 전투 · 피격 | D13: TC-CMB-07 적 공격이 체력을 깎는다 | E13: 새 런 시작 · 전투방 1 · 적 1마리 이상 생존 · 활성 무기 검 | F13: 1. HUD 체력 구슬의 현재 상태를 본다 2. 적 공격에 한 번 맞는다 3. HUD 체력이 줄어드는지 본다 | G13: 맞으면 HUD 체력이 줄어든다 | H13: Pass | I13: Pass | N13: 2026-10-03
A14: 13 | B14: 전투 · 피격 | C14: 전투 · 피격 | D14: TC-CMB-08 공중 공격 후 착지 | E14: 새 런 시작 · 전투방 1 · 적 1마리 이상 생존 · 활성 무기 검 | F14: 1. Space 로 점프한다 2. 공중에서 F 로 공격한다 3. 공격 모션이 끝나기 전에 착지한다 4. 착지 직후 ← → 입력으로 이동이 되는지 본다 | G14: 착지 후에는 공격 중 이동이 막힌다 | H14: Fail | I14: Fail | J14: 이연 — 근거가 기록에 있는 미해결 | N14: 2026-10-03
A15: 14 | B15: 무기 스왑 | C15: 무기 스왑 | D15: TC-SWAP-01 외형과 모션이 함께 바뀐다 | E15: 새 런 시작 · 무기 2자루 보유 · 스왑 게이지 가득 | F15: 1. 현재 플레이어 외형과 HUD 슬롯 표시를 본다 2. A 로 무기를 바꾼다 3. 외형이 바뀐 뒤 F 로 공격해 모션도 바뀌었는지 본다 | G15: 스프라이트·애니메이션이 동시에 교체된다 | H15: Pass | I15: Pass | N15: 2026-10-03
A16: 15 | B16: 무기 스왑 | C16: 무기 스왑 | D16: TC-SWAP-02 스왑 대시의 무적 | E16: 새 런 시작 · 무기 2자루 보유 · 스왑 게이지 가득 | F16: 1. 적 공격 예고가 뜨는 것을 보고 그 앞에 선다 2. 공격이 닿는 타이밍에 A 를 누른다 3. HUD 체력이 줄어드는지 본다 | G16: 대시 중 적 공격에 체력이 안 깎인다 | H16: Pass | I16: Pass | N16: 2026-10-03
A17: 16 | B17: 무기 스왑 | C17: 무기 스왑 | D17: TC-SWAP-03 쿨타임 중 스왑 차단 | E17: 새 런 시작 · 무기 2자루 보유 · 스왑 게이지 가득 | F17: 1. A 로 무기를 바꾼다 2. 스왑 게이지가 차기 전에 A 를 다시 누른다 3. 무기가 바뀌는지 · 게이지가 초기화되는지 본다 | G17: 게이지가 안 찼으면 입력이 무시된다 | H17: Pass | I17: Pass | N17: 2026-10-03
A18: 17 | B18: 무기 스왑 | C18: 무기 스왑 | D18: TC-SWAP-04 스왑 순간의 잔상 | E18: 새 런 시작 · 무기 2자루 보유 · 스왑 게이지 가득 | F18: 1. A 로 무기를 바꾼다 2. 교체 순간을 영상으로 녹화하거나 연속 캡처한다 3. 프레임을 넘겨 보며 옛 무기 그림이 한 프레임이라도 남는지 본다 | G18: 교체 순간 옛 무기 그림이 한 프레임도 안 보인다 | H18: Pass | I18: Pass | N18: 2026-10-03
A19: 18 | B19: 무기 스왑 | C19: 무기 스왑 | D19: TC-SWAP-05 무기 이름 표시 | E19: 새 런 시작 · 무기 2자루 보유 · 스왑 게이지 가득 | F19: 1. HUD 무기 슬롯 두 칸의 글자를 읽는다 2. A 로 바꾼 뒤 다시 읽는다 3. 검 처럼 읽히는지, weapon.sword.name 같은 키가 보이는지 본다 | G19: 로컬라이즈 키가 아니라 검 처럼 읽힌다 | H19: Pass | I19: Pass | N19: 2026-10-03
A20: 19 | B20: 무기 스왑 | C20: 무기 스왑 | D20: TC-SWAP-06 스왑 중 조작 차단 | E20: 새 런 시작 · 무기 2자루 보유 · 스왑 게이지 가득 | F20: 1. A 를 눌러 대시를 시작한다 2. 대시가 끝나기 전에 ← → · Space · F · A 를 차례로 누른다 3. 넷 중 하나라도 반응하는지 본다 | G20: 대시 중 이동·점프·공격·재스왑이 전부 안 먹는다 | H20: Pass | I20: Pass | N20: 2026-10-03
A21: 20 | B21: 무기 · 투사체 | C21: 무기 · 투사체 | D21: TC-WPN-01 무기 3종이 다르게 느껴진다 | E21: 검 · 창 · 활을 한 런에서 모두 얻은 상태 | F21: 1. 검으로 적을 때려 닿는 거리와 타격 간격을 본다 2. 창으로 바꿔 같은 거리에서 때려 본다 3. 활로 바꿔 같은 거리에서 쏴 본다 4. 셋의 사거리와 리듬이 구분되는지 본다 | G21: 검·창·활의 사거리와 리듬이 구분된다 | H21: Pass | I21: Pass | N21: 2026-10-03
A22: 21 | B22: 무기 · 투사체 | C22: 무기 · 투사체 | D22: TC-WPN-02 화살이 맞고 사라진다 | E22: 활을 활성 무기로 | F22: 1. 적을 향해 F 로 화살을 쏜다 2. 명중한 뒤 화살이 화면에 남는지 본다 3. 플레이어 쪽으로도 쏴서 자기 피해가 들어가는지 본다 | G22: 명중하면 소멸하고 발사자는 안 때린다 | H22: Pass | I22: Pass | N22: 2026-10-03
A23: 22 | B23: 무기 · 투사체 | C23: 무기 · 투사체 | D23: TC-WPN-03 화면 밖 화살이 안 쌓인다 | E23: 활을 활성 무기로 · 에디터 또는 빌드 · 프레임 표시 수단 준비 | F23: 1. 적이 없는 방향으로 F 를 3분 이상 연타한다 2. 프레임을 관찰한다 3. 에디터면 Hierarchy 에서 화살 오브젝트 수가 계속 늘어나는지 본다 | G23: 몇 분 돌려도 프레임이 안 떨어진다 | H23: Pass | I23: Pass | N23: 2026-10-03
A24: 23 | B24: 무기 · 투사체 | C24: 무기 · 투사체 | D24: TC-WPN-04 창이 빌드에 들어있다 | E24: 빌드 실행 · 새 런 시작 | F24: 1. 빌드를 실행해 새 런을 시작한다 2. 보상방에서 무기 카드를 받아 세 무기를 순서대로 모은다 3. 검 · 창 · 활 셋을 런 안에서 전부 손에 쥘 수 있는지 본다 | G24: 세 무기를 런 안에서 전부 쓸 수 있다 | H24: Pass | I24: Pass | N24: 2026-10-03
A25: 24 | B25: 무기 · 투사체 | C25: 무기 · 투사체 | D25: TC-WPN-05 강화가 적용된다 | E25: Unity 에디터 열림 · Test Runner EditMode | F25: 1. Unity 에디터에서 Window > General > Test Runner 를 연다 2. EditMode 탭의 WeaponInstanceTests 를 펼친다 3. 강화_1레벨에_데미지가_최소_1은_오른다 · 원본이_크면_배율이_가드를_이긴다 · 강화하면_선딜과_후딜이_줄어든다 · 강화해도_activeTime_은_안_변한다 넷을 실행한다 | G25: 강화 후 같은 적을 더 적은 타수로 잡는다 | H25: Pass | I25: Pass | J25: 수동 확인 + 자동 테스트 | N25: 2026-10-03
A26: 25 | B26: 무기 · 투사체 | C26: 무기 · 투사체 | D26: TC-WPN-06 강화가 원본 에셋을 오염시키지 않는다 | E26: Unity 에디터 열림 · Test Runner EditMode | F26: 1. Test Runner 의 EditMode 탭에서 WeaponInstanceTests 를 펼친다 2. GetAttack_은_원본_SO_를_바꾸지_않는다 · 강화_0레벨이면_원본_그대로다 둘을 실행한다 | G26: 플레이 모드를 넘어 WeaponData 가 그대로다 | H26: Pass | I26: Pass | J26: 자동 테스트가 판정 | N26: 2026-09-24
A27: 26 | B27: 무기 · 투사체 | C27: 무기 · 투사체 | D27: TC-WPN-07 강화 계산의 경계 | E27: Unity 에디터 열림 · Test Runner EditMode | F27: 1. Test Runner 의 EditMode 탭에서 WeaponInstanceTests 를 펼친다 2. 생성자에_음수_레벨을_주면_0_이_된다 · Upgrade_는_0_이하를_무시한다 둘을 실행한다 | G27: 레벨당 최소 +1 · 음수 레벨은 0 으로 | H27: Pass | I27: Pass | J27: 자동 테스트가 판정 | N27: 2026-09-24
A28: 27 | B28: 적 · 보스 | C28: 적 · 보스 | D28: TC-ENM-01 추격 → 예고 → 공격 → 경직 | E28: 전투방 · 돌진형 적 생존 | F28: 1. 적의 시야 밖에서 천천히 다가간다 2. 적이 따라오기 시작하는 지점을 본다 3. 예고 색이 뜨고, 공격이 나가고, 공격 뒤 적이 멈추는 것까지 순서대로 본다 | G28: 네 단계가 순서대로 보인다 | H28: Pass | I28: Pass | N28: 2026-10-03
A29: 28 | B29: 적 · 보스 | C29: 적 · 보스 | D29: TC-ENM-02 예고 색이 빌드에서 읽힌다 | E29: 빌드 실행 · 전투방 · 잡몹 생존 | F29: 1. 적에게 다가가 공격 예고가 뜨게 한다 2. 예고 순간 적 스프라이트 색을 본다 3. 색이 바뀐 것을 화면에서 알 수 있는지 판정한다 | G29: 공격 직전 색 변화가 화면에 나온다 | H29: Pass | I29: Pass | N29: 2026-10-03
A30: 29 | B30: 적 · 보스 | C30: 적 · 보스 | D30: TC-ENM-03 피격이 적 행동을 끊는다 | E30: 전투방 · 적 생존 | F30: 1. 적에게 다가가 예고가 뜨게 한다 2. 예고 중에 F 로 때린다 3. 예고와 공격이 중단되는지 본다 | G30: 때리면 예고·공격이 중단된다 (#79) | H30: Pass | I30: Pass | N30: 2026-10-03
A31: 30 | B31: 적 · 보스 | C31: 적 · 보스 | D31: TC-ENM-04 시체가 안 때린다 | E31: 전투방 · 적 생존 | F31: 1. 적이 공격 모션을 시작하게 만든다 2. 공격이 닿기 전에 마지막 타로 적을 처치한다 3. 시체가 사라지는 동안 몸을 겹쳐 두고 체력이 줄어드는지 본다 | G31: 죽은 적의 공격 판정이 남지 않는다 (#55) | H31: Pass | I31: Pass | N31: 2026-10-03
A32: 31 | B32: 적 · 보스 | C32: 적 · 보스 | D32: TC-ENM-05 거리로 패턴이 갈린다 | E32: 돌진형 적 생존 | F32: 1. 적에게 몸이 닿을 만큼 붙어 공격을 받는다 2. 어떤 패턴이 나오는지 적는다 3. 화면 반 폭쯤 떨어져 다시 공격을 받는다 4. 두 거리에서 나온 패턴이 다른지 본다 | G32: 붙으면 물기, 떨어지면 돌진이 나온다 | H32: Pass | I32: Pass | N32: 2026-10-03
A33: 32 | B33: 적 · 보스 | C33: 적 · 보스 | D33: TC-ENM-06 적 역할이 외형으로 갈린다 | E33: 돌진형과 원거리형이 같은 방에 있는 상태 | F33: 1. 방에 들어간 직후, 적에게 다가가기 전에 화면을 본다 2. 두 적의 외형만 보고 어느 쪽이 원거리형인지 지목한다 3. 다가가서 실제 행동으로 맞는지 확인한다 | G33: 붙기 전에 돌진형·원거리형을 구분할 수 있다 | H33: Pass | I33: Fail | J33: 과거 빌드에서 실패 → 수정됨 | N33: 2026-10-03
A34: 33 | B34: 적 · 보스 | C34: 적 · 보스 | D34: TC-ENM-07 원거리 적이 물러선다 | E34: 원거리형 적 생존 | F34: 1. 원거리형 적에게 정면으로 걸어간다 2. 사거리 안으로 들어갈 때 적의 발 위치를 본다 3. 적이 뒤로 물러나는지 본다 | G34: 플레이어가 붙으면 거리를 벌린다 (#108) | H34: Pass | I34: Pass | N34: 2026-10-03
A35: 34 | B35: 적 · 보스 | C35: 적 · 보스 | D35: TC-ENM-08 보스 3패턴이 전부 나온다 | E35: 보스방 진입 · 체력 여유 | F35: 1. 보스와 몸이 닿는 거리에서 버틴다 — Smash(0~1.8) 2. 조금 물러나 중거리를 유지한다 — Charge(1.6~3.5) 3. 화면 폭만큼 멀리 떨어진다 — Throw(3~10) 4. 세 패턴을 한 보스전에서 모두 봤는지 적는다 | G35: 한 보스전에서 셋을 다 본다 | H35: Pass | I35: Pass | N35: 2026-10-03
A36: 35 | B36: 적 · 보스 | C36: 적 · 보스 | D36: TC-ENM-09 보스 패턴은 안 끊긴다 | E36: 보스방 진입 | F36: 1. 보스가 패턴을 시작하게 만든다 2. 예고 중에 F 로 연타한다 3. 보스 공격이 중단되는지 본다 | G36: 때려도 보스 공격이 중단되지 않는다 | H36: Pass | I36: Pass | N36: 2026-10-03
A37: 36 | B37: 적 · 보스 | C37: 적 · 보스 | D37: TC-ENM-10 패턴 사거리가 구멍 없이 덮인다 | E37: Unity 에디터 열림 · Test Runner EditMode | F37: 1. Test Runner 의 EditMode 탭에서 AssetDataTests 를 펼친다 2. 모든_패턴이_minRange_보다_maxRange_가_크다 · 보스_패턴이_0부터_10까지_구멍_없이_덮는다 · 근접_패턴_둘이_겹치고_가중치가_3대1_이다 · 근접은_높이_제한이_있고_원거리는_없다 넷을 실행한다 | G37: 보스 010 · 근접에는 높이 제한이 있다 | H37: Pass | I37: Pass | J37: 자동 테스트가 판정 | N37: 2026-09-24
A38: 37 | B38: 적 · 보스 | C38: 적 · 보스 | D38: TC-ENM-11 보스도 예고 색이 읽힌다 | E38: 보스방 진입 | F38: 1. 보스가 패턴을 시작할 때까지 거리를 유지한다 2. 예고 구간(0.4~0.8초)에 보스 스프라이트 색을 본다 3. 색 변화를 화면에서 알 수 있는지 판정하고 그 순간을 캡처한다 | G38: 공격 직전 보스 스프라이트 색이 변한다 | H38: Pass | I38: Fail | K38: #150 | L38: Major | M38: High | N38: 2026-10-03
A39: 38 | B39: 방 · 스테이지 | C39: 방 · 스테이지 | D39: TC-ROOM-01 방이 연달아 전환된다 | E39: 전투방 · 적 처치 전 | F39: 1. 전투방의 적을 전부 처치한다 2. 열린 출구 포탈까지 이동한다 3. 포탈을 밟아 다음 방으로 넘어가는지 본다 | G39: 출구 포탈로 다음 방에 들어간다 | H39: Pass | I39: Pass | N39: 2026-10-03
A40: 39 | B40: 방 · 스테이지 | C40: 방 · 스테이지 | D40: TC-ROOM-02 방 타입이 핸들러로 갈린다 | E40: 새 런 시작 | F40: 1. 전투방에 들어가 무엇이 일어나는지 적는다 — 적이 나오는가 2. 보상방에 들어가 무엇이 일어나는지 적는다 — 카드가 뜨는가 3. 보스방에 들어가 무엇이 일어나는지 적는다 — 보스가 나오는가 4. 셋이 서로 다르게 동작하는지 본다 | G40: 전투·보상·보스방이 각각 다르게 동작한다 | H40: Pass | I40: Pass | N40: 2026-10-03
...

Sheet 결과 보고서
A1: 1회전 테스트 결과 보고서
A2: 대상 빌드 v1.0 (2026-09-03 제출본) · 수행 2026-09-23 ~ 09-24 · 세션 8회
A4: 테스트 정보
A5: 담당 QA | B5: 손주환 (1명)
A6: 테스트 기간 | B6: 2026-09-23 ~ 2026-09-24
A7: 테스트 빌드 | B7: v1.0 · Windows x64
A8: 플랫폼 | B8: Windows · 단독 실행
A9: 테스트 환경 | B9: Windows 11 Home 24H2 · Ryzen 5 9600X · RX 9070 XT · 32GB · 2560×1440
A10: 엔진 | B10: Unity 6000.3.15f1 · URP 2D
A11: 테스트 방법 | B11: 수동(빌드) + 수동(에디터) + 자동(EditMode 21개)
A14: 영역별 테스트 요약
A15: 영역 | B15: Pass | C15: Fail | D15: N/A | E15: Total | F15: 성공률
A16: 이동 · 점프 | B16: =COUNTIFS('TC 목록'!$B$2:$B$110,$A16,'TC 목록'!$H$2:$H$110,"Pass") | C16: =COUNTIFS('TC 목록'!$B$2:$B$110,$A16,'TC 목록'!$H$2:$H$110,"Fail") | D16: =COUNTIFS('TC 목록'!$B$2:$B$110,$A16,'TC 목록'!$H$2:$H$110,"N/A") | E16: =COUNTIF('TC 목록'!$B$2:$B$110,$A16) | F16: =IFERROR(B16/E16,0)
A17: 전투 · 피격 | B17: =COUNTIFS('TC 목록'!$B$2:$B$110,$A17,'TC 목록'!$H$2:$H$110,"Pass") | C17: =COUNTIFS('TC 목록'!$B$2:$B$110,$A17,'TC 목록'!$H$2:$H$110,"Fail") | D17: =COUNTIFS('TC 목록'!$B$2:$B$110,$A17,'TC 목록'!$H$2:$H$110,"N/A") | E17: =COUNTIF('TC 목록'!$B$2:$B$110,$A17) | F17: =IFERROR(B17/E17,0)
A18: 무기 스왑 | B18: =COUNTIFS('TC 목록'!$B$2:$B$110,$A18,'TC 목록'!$H$2:$H$110,"Pass") | C18: =COUNTIFS('TC 목록'!$B$2:$B$110,$A18,'TC 목록'!$H$2:$H$110,"Fail") | D18: =COUNTIFS('TC 목록'!$B$2:$B$110,$A18,'TC 목록'!$H$2:$H$110,"N/A") | E18: =COUNTIF('TC 목록'!$B$2:$B$110,$A18) | F18: =IFERROR(B18/E18,0)
A19: 무기 · 투사체 | B19: =COUNTIFS('TC 목록'!$B$2:$B$110,$A19,'TC 목록'!$H$2:$H$110,"Pass") | C19: =COUNTIFS('TC 목록'!$B$2:$B$110,$A19,'TC 목록'!$H$2:$H$110,"Fail") | D19: =COUNTIFS('TC 목록'!$B$2:$B$110,$A19,'TC 목록'!$H$2:$H$110,"N/A") | E19: =COUNTIF('TC 목록'!$B$2:$B$110,$A19) | F19: =IFERROR(B19/E19,0)
A20: 적 · 보스 | B20: =COUNTIFS('TC 목록'!$B$2:$B$110,$A20,'TC 목록'!$H$2:$H$110,"Pass") | C20: =COUNTIFS('TC 목록'!$B$2:$B$110,$A20,'TC 목록'!$H$2:$H$110,"Fail") | D20: =COUNTIFS('TC 목록'!$B$2:$B$110,$A20,'TC 목록'!$H$2:$H$110,"N/A") | E20: =COUNTIF('TC 목록'!$B$2:$B$110,$A20) | F20: =IFERROR(B20/E20,0)
A21: 방 · 스테이지 | B21: =COUNTIFS('TC 목록'!$B$2:$B$110,$A21,'TC 목록'!$H$2:$H$110,"Pass") | C21: =COUNTIFS('TC 목록'!$B$2:$B$110,$A21,'TC 목록'!$H$2:$H$110,"Fail") | D21: =COUNTIFS('TC 목록'!$B$2:$B$110,$A21,'TC 목록'!$H$2:$H$110,"N/A") | E21: =COUNTIF('TC 목록'!$B$2:$B$110,$A21) | F21: =IFERROR(B21/E21,0)
A22: 런 루프 · 보상 | B22: =COUNTIFS('TC 목록'!$B$2:$B$110,$A22,'TC 목록'!$H$2:$H$110,"Pass") | C22: =COUNTIFS('TC 목록'!$B$2:$B$110,$A22,'TC 목록'!$H$2:$H$110,"Fail") | D22: =COUNTIFS('TC 목록'!$B$2:$B$110,$A22,'TC 목록'!$H$2:$H$110,"N/A") | E22: =COUNTIF('TC 목록'!$B$2:$B$110,$A22) | F22: =IFERROR(B22/E22,0)
A23: UI · 설정 · 로컬라이즈 | B23: =COUNTIFS('TC 목록'!$B$2:$B$110,$A23,'TC 목록'!$H$2:$H$110,"Pass") | C23: =COUNTIFS('TC 목록'!$B$2:$B$110,$A23,'TC 목록'!$H$2:$H$110,"Fail") | D23: =COUNTIFS('TC 목록'!$B$2:$B$110,$A23,'TC 목록'!$H$2:$H$110,"N/A") | E23: =COUNTIF('TC 목록'!$B$2:$B$110,$A23) | F23: =IFERROR(B23/E23,0)
A24: 소리 | B24: =COUNTIFS('TC 목록'!$B$2:$B$110,$A24,'TC 목록'!$H$2:$H$110,"Pass") | C24: =COUNTIFS('TC 목록'!$B$2:$B$110,$A24,'TC 목록'!$H$2:$H$110,"Fail") | D24: =COUNTIFS('TC 목록'!$B$2:$B$110,$A24,'TC 목록'!$H$2:$H$110,"N/A") | E24: =COUNTIF('TC 목록'!$B$2:$B$110,$A24) | F24: =IFERROR(B24/E24,0)
A25: 경계 · 비정상 흐름 | B25: =COUNTIFS('TC 목록'!$B$2:$B$110,$A25,'TC 목록'!$H$2:$H$110,"Pass") | C25: =COUNTIFS('TC 목록'!$B$2:$B$110,$A25,'TC 목록'!$H$2:$H$110,"Fail") | D25: =COUNTIFS('TC 목록'!$B$2:$B$110,$A25,'TC 목록'!$H$2:$H$110,"N/A") | E25: =COUNTIF('TC 목록'!$B$2:$B$110,$A25) | F25: =IFERROR(B25/E25,0)
A26: 빌드 전 정적 확인 | B26: =COUNTIFS('TC 목록'!$B$2:$B$110,$A26,'TC 목록'!$H$2:$H$110,"Pass") | C26: =COUNTIFS('TC 목록'!$B$2:$B$110,$A26,'TC 목록'!$H$2:$H$110,"Fail") | D26: =COUNTIFS('TC 목록'!$B$2:$B$110,$A26,'TC 목록'!$H$2:$H$110,"N/A") | E26: =COUNTIF('TC 목록'!$B$2:$B$110,$A26) | F26: =IFERROR(B26/E26,0)
A27: 합계 | B27: =SUM(B16:B26) | C27: =SUM(C16:C26) | D27: =SUM(D16:D26) | E27: =SUM(E16:E26) | F27: =IFERROR(B27/E27,0)
A30: 결과 리포트
A31: 미확인 0건 | B31: 시작 시 △ 6건이 전부 해소됐다. 확인 못 한 항목을 통과로 적지 않는 것이 이 표의 규칙이므로, 0 은 모든 항목에 대해 봤거나 못 본 이유가 적혀 있다는 뜻이다.
A32: Major 셋의 공통점 | B32: #153 #150 #149 는 전부 "동작은 하는데 읽을 수 없다"에 해당한다. #150 은 보스 패턴이 안 끊기므로 예고가 유일한 회피 신호라는 점에서 특히 무겁다.
A33: #149 가 Critical 이 아닌 이유 | B33: TC-EDGE-14(재선택 불가)가 통과해, 패널이 남아도 보상이 두 번 적용되지 않는 것을 확인했다.
A34: Trivial 을 남긴 이유 | B34: #154 는 매 실행마다 뜨는 오탐 경고다. 두면 진짜 배선 누락이 같은 줄에 섞인다 — W3 에서 HurtBox.health 를 놓친 것이 그 종류였다.
A35: 과거 수정분 4건 | B35: TC-UI-01 · UI-07 · ROOM-04 · RUN-08 의 수정이 유지되는 것을 확인했다. ROOM-04 는 자동 테스트로 승격돼 사람이 다시 안 본다.
A36: 이연 1건 | B36: TC-CMB-08 은 재현됐고 고치지 않는다. 범위가 1차에 없다는 근거가 기록에 있고, 이번 수행의 목적은 그 판단이 유효한지 보는 것이었다.
A37: 실패의 출처 | B37: 신규 7건 중 셋(UI-12 · UI-13 · BLD-10)이 수행 목록이 아니라 캡처와 로그에서 나왔다. 2회전에는 캡처 검토와 로그 확인을 세션 단계로 넣는다.
A38: TC 자체의 결함 | B38: 존재하지 않는 조작(EDGE-22) · 한 항목이 두 대상(EDGE-23) · 규칙이 다른 둘을 묶음(ENM-03). 수행은 제품만이 아니라 TC 도 검사한다.

Sheet 자동화
A1: NO | B1: 영역 | C1: 테스트 클래스 | D1: 테스트 이름 | E1: 대응 TC | F1: 이슈 | G1: 결과
A2: 1 | B2: 런 구성 | C2: RunStateTests | D2: 같은 시드는 같은 방 순서다 | E2: TC-ROOM-05 | F2: #141 | G2: Pass
A3: 2 | B3: 런 구성 | C3: RunStateTests | D3: 한 런에 전투방이 겹치지 않는다 | E3: TC-ROOM-04 | F3: #141 | G3: Pass
A4: 3 | B4: 런 구성 | C4: RunStateTests | D4: 덱 경계에서 같은 방이 연속되지 않는다 | E4: TC-ROOM-07 | F4: #141 | G4: Pass
A5: 4 | B5: 런 구성 | C5: RunStateTests | D5: 시드가 다르면 순서도 달라진다 | E5: TC-ROOM-08 | F5: #141 | G5: Pass
A6: 5 | B6: 전투 수치 | C6: WeaponInstanceTests | D6: 강화 0레벨이면 원본 그대로다 | E6: TC-WPN-05 | F6: #144 | G6: Pass
A7: 6 | B7: 전투 수치 | C7: WeaponInstanceTests | D7: 강화 1레벨에 데미지가 최소 1은 오른다 | E7: TC-WPN-07 | F7: #144 | G7: Pass
A8: 7 | B8: 전투 수치 | C8: WeaponInstanceTests | D8: 원본이 크면 배율이 가드를 이긴다 | E8: TC-WPN-07 | F8: #144 | G8: Pass
A9: 8 | B9: 전투 수치 | C9: WeaponInstanceTests | D9: 강화해도 activeTime 은 안 변한다 | E9: TC-WPN-05 | F9: #144 | G9: Pass
A10: 9 | B10: 전투 수치 | C10: WeaponInstanceTests | D10: 강화하면 선딜과 후딜이 줄어든다 | E10: TC-WPN-05 | F10: #144 | G10: Pass
A11: 10 | B11: 전투 수치 | C11: WeaponInstanceTests | D11: GetAttack 은 원본 SO 를 바꾸지 않는다 | E11: TC-WPN-06 | F11: #144 | G11: Pass
A12: 11 | B12: 전투 수치 | C12: WeaponInstanceTests | D12: 생성자에 음수 레벨을 주면 0 이 된다 | E12: TC-WPN-07 | F12: #144 | G12: Pass
A13: 12 | B13: 전투 수치 | C13: WeaponInstanceTests | D13: Upgrade 는 0 이하를 무시한다 | E13: TC-WPN-07 | F13: #144 | G13: Pass
... A22: 21 | B22: 에셋 데이터 | C22: AssetDataTests | D22: 근접은 높이 제한이 있고 원거리는 없다 | E22: TC-ENM-10 | F22: #146 | G22: Pass
A24: EditMode 테스트 21개. Unity Test Runner 에서 실행하며 씬·플레이 모드가 필요 없다.
A25: 계산 검증은 SerializedObject 로 만든 픽스처를, 데이터 검증은 AssetDatabase 로 읽은 실제 에셋을 쓴다.

Sheet 결함
A1: NO | B1: 이슈 | C1: 제목 | D1: 발견 TC | E1: 발견 세션 | F1: 중요도 | G1: 우선순위 | H1: 재현율 | I1: 첨부
A2: 1 | B2: #153 | C2: 영어 결과 화면에서 요약 텍스트가 안내와 겹친다 | D2: TC-UI-13 | E2: 세션 6 | F2: Major | G2: High | H2: 3/3 | I2: result_en.png · result.png
A3: 2 | B3: #149 | C3: 숫자키로 보상을 고르면 선택 패널이 안 닫힌다 | D3: TC-RUN-10 | E3: 세션 3 | F3: Major | G3: High | H3: 3/3 | I3: reward.png
A4: 3 | B4: #150 | C4: 보스는 공격 예고 색이 보이지 않는다 | D4: TC-ENM-11 | E4: 세션 3 | F4: Major | G4: High | H4: 3/3 | I4: boss.png
A5: 4 | B5: #152 | C5: 해상도를 바꾸면 일시정지 설정창의 위치가 어긋난다 | D5: TC-EDGE-28 | E5: 세션 5 | F5: Minor | G5: Normal | H5: 3/3 | I5: pause.png
A6: 5 | B6: #148 | C6: 조작 안내에 보상 선택 키가 없다 | D6: TC-UI-11 | E6: 세션 1 | F6: Minor | G6: Normal | H6: 3/3 | I6: controls.png · controls_en.png
A7: 6 | B7: #151 | C7: 보상 카드가 2개일 때 오른쪽이 빈 채로 남는다 | D7: TC-UI-12 | E7: 세션 4 | F7: Trivial | G7: Low | H7: 3/3 | I7: reward.png
A8: 7 | B8: #154 | C8: 전투 씬에서 의도한 구성인데 배선 경고가 찍힌다 | D8: TC-BLD-10 | E8: 세션 8 | F8: Trivial | G8: Low | H8: 3/3 | I8: Player.log

Sheet 범위 밖 · 이연
A1: 구분 | B1: 항목 | C1: 사유
A2: 범위 밖 | B2: 게임패드 | C2: 바인딩은 있으나 이번 회전에서 확인하지 않기로 정했다
A3: 범위 밖 | B3: 다른 PC | C3: 테스트 환경이 한 대뿐이다
A4: 범위 밖 | B4: 다른 해상도 모니터 | C4: 2560×1440 하나로만 확인했다
A5: 범위 밖 | B5: 배포 · 설치 | C5: 단독 실행이라 설치 과정이 없다
A6: 범위 밖 | B6: 네트워크 | C6: 싱글플레이다
A7: 이연 | B7: TC-CMB-08 공중 공격 후 착지 | C7: 재현됨. 고치지 않은 근거가 기록에 있다 — 범위가 1차에 없다
A8: 해당 없음 | B8: TC-EDGE-22 정지 중 언어 변경 | C8: 전투 씬 설정에 언어 항목이 없어 조작 자체가 성립하지 않는다
A10: 못 한 것과 안 하기로 한 것은 다르다. 범위 밖은 정한 것이고, 미확인(△)은 0건이다.
